#VRML_SIM R2025a utf8

EXTERNPROTO "https://raw.githubusercontent.com/cyberbotics/webots/R2025a/projects/objects/backgrounds/protos/TexturedBackground.proto"
EXTERNPROTO "https://raw.githubusercontent.com/cyberbotics/webots/R2025a/projects/objects/backgrounds/protos/TexturedBackgroundLight.proto"

WorldInfo {
  gravity 3.71
}
Viewpoint {
  orientation 0.34231130309060226 0.1125625846070727 -0.9328197233779899 2.853247118212075
  position 106.88227309353763 67.03297423436669 103.3687518754106
}
TexturedBackground {
  texture "mars"
}
TexturedBackgroundLight {
  texture "mars"
}
Robot {
  translation -8.844514863610723 24.638588834848846 6.0545331338222965
  rotation 0.00035292870465840695 0.00026493382146769033 0.999999902625695 2.7901245666859493
  children [
    Transform {
      translation 0.0500249 2.05 -0.29
      rotation 0 0 1 3.14159
      scale 0.02 0.02 0.02
      children [
        Shape {
          appearance PBRAppearance {
            baseColorMap ImageTexture {
              url [
                "../mesh/Design sem nome (2).png"
              ]
            }
            roughness 1
            metalness 0
            textureTransform TextureTransform {
              scale 0.0005 0.0005
            }
          }
          geometry Mesh {
            url [
              "../mesh/GS2026-Hover-Chassi.obj"
            ]
          }
          castShadows FALSE
        }
      ]
    }
    DistanceSensor {
      translation 0.07 2.53 1.15
      rotation 0 1 0 0
      name "prox_front"
      lookupTable [
        0 1000 0
        0.5 500 0
        1.5 0 0
      ]
      type "infra-red"
    }
    DistanceSensor {
      translation -1.03621 0.25 0.765107
      rotation 0 1 0 -0.45
      name "prox_front_left"
      lookupTable [
        0 1000 0
        0.5 500 0
        1.5 0 0
      ]
      type "infra-red"
    }
    DistanceSensor {
      translation 0.999756 0.25 0.85087
      rotation 0 1 0 -0.45
      name "prox_front_right"
      lookupTable [
        0 1000 0
        0.5 500 0
        1.5 0 0
      ]
      type "infra-red"
    }
    DistanceSensor {
      translation -1.05 0.25 0
      rotation 0 1 0 -1.5708
      name "prox_left"
      lookupTable [
        0 1000 0
        0.5 500 0
        1.5 0 0
      ]
      type "infra-red"
    }
    DistanceSensor {
      translation 1.05 0.25 0
      rotation 0 1 0 -1.5708
      name "prox_right"
      lookupTable [
        0 1000 0
        0.5 500 0
        1.5 0 0
      ]
      type "infra-red"
    }
    Display {
      name "hud_display"
      width 1024
      height 900
    }
    Camera {
      translation 3.45715e-05 2.00616 0.906508
      rotation -0.12942697652524895 0.12942797652506757 0.9831058216896892 1.58783
      name "front_camera"
      fieldOfView 1.4
      width 640
      height 360
      near 0.05
      far 80
      lens Lens {
      }
      recognition Recognition {
      }
    }
    HingeJoint {
      jointParameters HingeJointParameters {
        position -31.40848838619381
        anchor -1.45 -1.35 -0.7
      }
      device [
        RotationalMotor {
          name "motor_front_left"
          maxTorque 100
        }
      ]
      endPoint Solid {
        translation -1.45 -1.35 -0.7
        rotation -0.5840923722137522 -0.5643101632097569 -0.5834296362200749 4.228437819254101
        children [
          Shape {
            appearance PBRAppearance {
              baseColor 0.02 0.02 0.02
              roughness 0.7
            }
            geometry Cylinder {
              height 0.4
              radius 0.36
            }
          }
        ]
        name "wheel_front_left"
        boundingObject Cylinder {
          height 0.4
          radius 0.36
        }
        physics Physics {
          density -1
          mass 5
        }
      }
    }
    HingeJoint {
      jointParameters HingeJointParameters {
        position 193.02670091868427
        anchor 1.55 -1.35 -0.7
      }
      device [
        RotationalMotor {
          name "motor_front_right"
          maxTorque 100
        }
      ]
      endPoint Solid {
        translation 1.55 -1.35 -0.7
        rotation 0.11410037447464373 -0.9904729146909294 0.07710064726317868 4.7342743214210525
        children [
          Shape {
            appearance PBRAppearance {
              baseColor 0.02 0.02 0.02
              roughness 0.7
            }
            geometry Cylinder {
              height 0.4
              radius 0.36
            }
          }
        ]
        name "wheel_front_right"
        boundingObject Cylinder {
          height 0.4
          radius 0.36
        }
        physics Physics {
          density -1
          mass 5
        }
      }
    }
    HingeJoint {
      jointParameters HingeJointParameters {
        position -31.107508804764443
        anchor -1.46 1.54 -0.7
      }
      device [
        RotationalMotor {
          name "motor_back_left"
          maxTorque 100
        }
      ]
      endPoint Solid {
        translation -1.46 1.54 -0.7
        rotation -0.6354855770917105 -0.44752504467651916 -0.6291894910880944 4.044487651748769
        children [
          Shape {
            appearance PBRAppearance {
              baseColor 0.02 0.02 0.02
              roughness 0.7
            }
            geometry Cylinder {
              height 0.4
              radius 0.36
            }
          }
        ]
        name "wheel_back_left"
        boundingObject Cylinder {
          height 0.4
          radius 0.36
        }
        physics Physics {
          density -1
          mass 5
        }
      }
    }
    HingeJoint {
      jointParameters HingeJointParameters {
        position 177.78313954644585
        anchor 1.54 1.54 -0.7
      }
      device [
        RotationalMotor {
          name "motor_back_right"
          maxTorque 100
        }
      ]
      endPoint Solid {
        translation 1.54 1.54 -0.7
        rotation 0.7166876761293635 -0.1073298431836892 0.689085683820566 3.315488070643731
        children [
          Shape {
            appearance PBRAppearance {
              baseColor 0.02 0.02 0.02
              roughness 0.7
            }
            geometry Cylinder {
              height 0.4
              radius 0.36
            }
          }
        ]
        name "wheel_back_right"
        boundingObject Cylinder {
          height 0.4
          radius 0.36
        }
        physics Physics {
          density -1
          mass 5
        }
      }
    }
    HingeJoint {
      jointParameters HingeJointParameters {
        position -31.3717659586083
        anchor -1.44 -0.46 -0.7
      }
      device [
        RotationalMotor {
          name "motor_mid_left"
          maxTorque 100
        }
      ]
      endPoint Solid {
        translation -1.44 -0.46 -0.7
        rotation -0.591265374207922 -0.5499501249559288 -0.5898814434475154 4.206850880167567
        children [
          Shape {
            appearance PBRAppearance {
              baseColor 0.02 0.02 0.02
              roughness 0.7
            }
            geometry Cylinder {
              height 0.4
              radius 0.36
            }
          }
        ]
        name "wheel_mid_left"
        boundingObject Cylinder {
          height 0.4
          radius 0.36
        }
        physics Physics {
          density -1
          mass 5
        }
      }
    }
    HingeJoint {
      jointParameters HingeJointParameters {
        position 191.7227895960906
        anchor 1.56 -0.45 -0.7
      }
      device [
        RotationalMotor {
          name "motor_mid_right"
          maxTorque 100
        }
      ]
      endPoint Solid {
        translation 1.56 -0.45 -0.7
        rotation 0.5819132165154433 -0.6062082617487409 0.5421148880377857 4.23478203044857
        children [
          Shape {
            appearance PBRAppearance {
              baseColor 0.02 0.02 0.02
              roughness 0.7
            }
            geometry Cylinder {
              height 0.4
              radius 0.36
            }
          }
        ]
        name "wheel_mid_right"
        boundingObject Cylinder {
          height 0.4
          radius 0.36
        }
        physics Physics {
          density -1
          mass 5
        }
      }
    }
  ]
  name "Mars_Hover"
  boundingObject Box {
    size 2 4 1.5
  }
  physics Physics {
    density -1
    mass 100
    centerOfMass [
      0 -0.12 0
    ]
    damping Damping {
      angular 1
    }
  }
  controller "mars_hover_controller"
  window "mars_hover_dashboard"
}
Solid {
  translation 0 -7.34 0
  children [
    Solid {
      translation 28.49 15.76 5.12516
      rotation 0.4907171512566385 0.33692277615318955 -0.8035419841998284 3.4240261593687747e-07
      children [
        Shape {
          appearance PBRAppearance {
            baseColor 1 0.3 0.3
            baseColorMap ImageTexture {
              url [
                "../textures/rock_material.png"
              ]
            }
            roughness 1
            normalMap ImageTexture {
              url [
                "../textures/rock_normal.png"
              ]
            }
          }
          geometry Capsule {
            height 1
            radius 5
          }
        }
      ]
      name "rock_1"
      boundingObject Capsule {
        height 1
        radius 5
        subdivision 16
      }
      physics Physics {
        density -1
        mass 500
      }
    }
    Solid {
      translation 37.44 35.91 5.12516
      rotation 0.4907171512566385 0.33692277615318955 -0.8035419841998284 3.4240261593687747e-07
      children [
        Shape {
          appearance PBRAppearance {
            baseColor 1 0.3 0.3
            baseColorMap ImageTexture {
              url [
                "../textures/rock_material.png"
              ]
            }
            roughness 1
            normalMap ImageTexture {
              url [
                "../textures/rock_normal.png"
              ]
            }
          }
          geometry Capsule {
            height 1
            radius 5
          }
        }
      ]
      name "rock_1(1)"
      boundingObject Capsule {
        height 1
        radius 5
        subdivision 16
      }
      physics Physics {
        density -1
        mass 500
      }
    }
    Solid {
      translation 22.76 45.27 5.12516
      rotation 0.4907171512566385 0.33692277615318955 -0.8035419841998284 3.4240261593687747e-07
      children [
        Shape {
          appearance PBRAppearance {
            baseColor 1 0.3 0.3
            baseColorMap ImageTexture {
              url [
                "../textures/rock_material.png"
              ]
            }
            roughness 1
            normalMap ImageTexture {
              url [
                "../textures/rock_normal.png"
              ]
            }
          }
          geometry Capsule {
            height 1
            radius 5
          }
        }
      ]
      name "rock_1(2)"
      boundingObject Capsule {
        height 1
        radius 5
        subdivision 16
      }
      physics Physics {
        density -1
        mass 500
      }
    }
    Solid {
      translation -4.05 11.59 5.122198451110534
      rotation 0.49071715125663856 0.3369227761531896 -0.8035419841998284 3.4240261593687747e-07
      children [
        Shape {
          appearance PBRAppearance {
            baseColor 1 0.3 0.3
            baseColorMap ImageTexture {
              url [
                "../textures/rock_material.png"
              ]
            }
            roughness 1
            normalMap ImageTexture {
              url [
                "../textures/rock_normal.png"
              ]
            }
          }
          geometry Capsule {
            height 1
            radius 5
          }
        }
      ]
      name "rock_3"
      boundingObject Capsule {
        height 1
        radius 5
        subdivision 16
      }
      physics Physics {
        density -1
        mass 500
      }
    }
    Solid {
      translation -48.7558 17.193 4.79219
      rotation -1.45698e-07 -2.23555e-07 1 -0.785395307179586
      children [
        Shape {
          appearance PBRAppearance {
            baseColor 1 0.3 0.3
            baseColorMap ImageTexture {
              url [
                "../textures/rock_material.png"
              ]
              filtering 5
            }
            roughness 1
            normalMap ImageTexture {
              url [
                "../textures/rock_normal.png"
              ]
            }
            textureTransform TextureTransform {
              scale 10 10
            }
          }
          geometry Box {
            size 100 10 15
          }
        }
      ]
      name "rock_2"
      boundingObject Box {
        size 100 10 15
      }
      physics Physics {
        density -1
        mass 500
      }
    }
    Solid {
      translation -53.2582 0.38612 4.79219
      rotation -6.94632e-09 -1.28527e-07 1 -1.8325953071795862
      children [
        Shape {
          appearance PBRAppearance {
            baseColor 1 0.3 0.3
            baseColorMap ImageTexture {
              url [
                "../textures/rock_material.png"
              ]
            }
            roughness 1
            normalMap ImageTexture {
              url [
                "../textures/rock_normal.png"
              ]
            }
            textureTransform TextureTransform {
              scale 10 10
            }
          }
          geometry Box {
            size 100 10 15
          }
        }
      ]
      name "rock_2(2)"
      boundingObject Box {
        size 100 10 15
      }
    }
    Solid {
      translation -6.48513 85.3584 4.79219
      rotation -1.45698e-07 -2.23555e-07 1 -0.785395307179586
      children [
        Shape {
          appearance PBRAppearance {
            baseColor 1 0.3 0.3
            baseColorMap ImageTexture {
              url [
                "../textures/rock_material.png"
              ]
              filtering 5
            }
            roughness 1
            normalMap ImageTexture {
              url [
                "../textures/rock_normal.png"
              ]
            }
            textureTransform TextureTransform {
              scale 10 10
            }
          }
          geometry Box {
            size 100 10 15
          }
        }
      ]
      name "rock_2(1)"
      boundingObject Box {
        size 100 10 15
      }
    }
    Transform {
      translation 0 -734 -11
      scale 500 500 10
      children [
        Shape {
          appearance PBRAppearance {
            baseColorMap ImageTexture {
              url [
                "../textures/mars_soil.png"
              ]
            }
            roughness 1
            metalness 0
            metalnessMap ImageTexture {
              url [
                "../martian_terrain/image0.png"
              ]
            }
            normalMap ImageTexture {
              url [
                "../textures/mars_soil_normal.png"
              ]
            }
            normalMapFactor 1.5
            textureTransform TextureTransform {
              scale 10 10
            }
          }
          geometry Mesh {
            url [
              "../martian_terrain/martian_terrain.obj"
            ]
          }
        }
      ]
    }
  ]
  name "Mars_Ground"
  boundingObject Box {
    size 1000 1000 10
  }
}
